<?xml version="1.0"?>

<robot name="penta_bot" xmlns:xacro="http://www.ros.org/wiki/xacro">

  <link name="base_footprint"/>

  <link name="base_link">
    <visual>
      <geometry>
        <cylinder radius="0.10" length="0.025"/>
      </geometry>
      <origin xyz="0.0 0.0 0.0" rpy="0 0 0"/>
    </visual>
  </link>

  <joint name="joint_robot_body_center" type="fixed">
    <parent link="base_footprint"/>
    <child link="base_link"/>
    <origin xyz="0.0 0.0 0.05" rpy="0 0 0"/>
  </joint>

  <xacro:macro name="leg" params="prefix shoulderxyz shoulderrpy">
    <link name="${prefix}_shoulder_motor">
      <visual>
        <geometry>
          <cylinder radius="0.0350" length="0.035"/>
        </geometry>
        <origin xyz="0.0 0.0 0.0" rpy="0 0 0"/>
      </visual>
    </link>

    <link name="${prefix}_shoulder_link">
      <visual>
        <geometry>
          <box size="0.1 0.02 0.02"/>
        </geometry>
        <origin xyz="0.05 0.0 0.0" rpy="0 0 0"/>
      </visual>
    </link>

    <link name="${prefix}_upper_arm_link">
      <visual>
        <geometry>
          <box size="0.1 0.02 0.02"/>
        </geometry>
        <origin xyz="0.05 0.0 0.0" rpy="0 0 0"/>
      </visual>
    </link>

    <link name="${prefix}_lower_arm_link">
      <visual>
        <geometry>
          <box size="0.1 0.02 0.02"/>
        </geometry>
        <origin xyz="0.05 0.0 0.0" rpy="0 0 0"/>
      </visual>
    </link>

    <joint name="${prefix}/joint_shoulder_motor" type="fixed">
      <parent link="base_link"/>
      <child link="${prefix}_shoulder_motor"/>
      <origin xyz="${shoulderxyz}" rpy="${shoulderrpy}"/>
    </joint>


    <joint name="${prefix}/joint0" type="continuous">
      <parent link="${prefix}_shoulder_motor"/>
      <child link="${prefix}_shoulder_link"/>
      <origin xyz="0.0 0.0 0.0" rpy="0 0 0"/>
      <axis xyz="0 0 1" />
    </joint>

    <joint name="${prefix}/joint1" type="continuous">
      <parent link="${prefix}_shoulder_link"/>
      <child link="${prefix}_upper_arm_link"/>
      <origin xyz="0.1 0.0 0.0" rpy="-1.57 0 0"/>
      <axis xyz="0 0 1" />
    </joint>


    <joint name="${prefix}/joint2" type="continuous">
      <parent link="${prefix}_upper_arm_link"/>
      <child link="${prefix}_lower_arm_link"/>
      <origin xyz="0.1 0.0 0.0" rpy="0 0 0"/>
      <axis xyz="0 0 1" />
    </joint>

  </xacro:macro>

<xacro:leg prefix="limb0" shoulderxyz="${0.1*cos(0.*3.141592/2.5)} ${0.1*sin(0.*3.141592/2.5)} 0." shoulderrpy="0. 0. ${(0.*3.141592/2.5)}"/>
<xacro:leg prefix="limb1" shoulderxyz="${0.1*cos(1.*3.141592/2.5)} ${0.1*sin(1.*3.141592/2.5)} 0." shoulderrpy="0. 0. ${(1.*3.141592/2.5)}"/>
<xacro:leg prefix="limb2" shoulderxyz="${0.1*cos(2.*3.141592/2.5)} ${0.1*sin(2.*3.141592/2.5)} 0." shoulderrpy="0. 0. ${(2.*3.141592/2.5)}"/>
<xacro:leg prefix="limb3" shoulderxyz="${0.1*cos(3.*3.141592/2.5)} ${0.1*sin(3.*3.141592/2.5)} 0." shoulderrpy="0. 0. ${(3.*3.141592/2.5)}"/>
<xacro:leg prefix="limb4" shoulderxyz="${0.1*cos(4.*3.141592/2.5)} ${0.1*sin(4.*3.141592/2.5)} 0." shoulderrpy="0. 0. ${(4.*3.141592/2.5)}"/>

</robot>
